<mujoco model="Adroit">
  <compiler angle="radian" />
  <option apirate="200" cone="elliptic" iterations="20" noslip_iterations="20" solver="PGS" />
  <size nconmax="500" njmax="2000" nstack="600000" nuser_actuator="16" nuser_body="9" nuser_jnt="1" nuser_sensor="1" nuser_site="1" nuser_tendon="1" />
  <default /><asset>
    <material name="MatColl" reflectance="0.5" rgba="0.4 0.5 0.6 1" shininess="0.3" specular="1" />
    <material name="MatViz" reflectance="0.5" rgba="0.9 0.7 0.5 1" shininess="0.1" specular="0.75" />
    <mesh file="/home/martina/dexmv-sim/hand_imitation/env/models/assets/adroit/meshes/forearm_simple.stl" name="forearm_simple" scale="1 1 1" />
    <mesh file="/home/martina/dexmv-sim/hand_imitation/env/models/assets/adroit/meshes/wrist.stl" name="wrist" scale="0.001 0.001 0.001" />
    <mesh file="/home/martina/dexmv-sim/hand_imitation/env/models/assets/adroit/meshes/palm.stl" name="palm" scale="0.001 0.001 0.001" />
    <mesh file="/home/martina/dexmv-sim/hand_imitation/env/models/assets/adroit/meshes/lfmetacarpal.stl" name="lfmetacarpal" scale="0.001 0.001 0.001" />
    <mesh file="/home/martina/dexmv-sim/hand_imitation/env/models/assets/adroit/meshes/knuckle.stl" name="knuckle" scale="0.001 0.001 0.001" />
    <mesh file="/home/martina/dexmv-sim/hand_imitation/env/models/assets/adroit/meshes/F3.stl" name="F3" scale="0.001 0.001 0.001" />
    <mesh file="/home/martina/dexmv-sim/hand_imitation/env/models/assets/adroit/meshes/F2.stl" name="F2" scale="0.001 0.001 0.001" />
    <mesh file="/home/martina/dexmv-sim/hand_imitation/env/models/assets/adroit/meshes/F1.stl" name="F1" scale="0.001 0.001 0.001" />
    <mesh file="/home/martina/dexmv-sim/hand_imitation/env/models/assets/adroit/meshes/TH3_z.stl" name="TH3_z" scale="0.001 0.001 0.001" />
    <mesh file="/home/martina/dexmv-sim/hand_imitation/env/models/assets/adroit/meshes/TH2_z.stl" name="TH2_z" scale="0.001 0.001 0.001" />
    <mesh file="/home/martina/dexmv-sim/hand_imitation/env/models/assets/adroit/meshes/TH1_z.stl" name="TH1_z" scale="0.001 0.001 0.001" />
  <texture builtin="gradient" height="256" rgb1=".9 .9 1." rgb2=".2 .3 .4" type="skybox" width="256" />
        <texture file="/home/martina/dexmv-sim/hand_imitation/env/models/assets/arenas/../textures/wood-tiles.png" name="texplane" type="2d" />
        <material name="floorplane" reflectance="0.01" shininess="0.0" specular="0.0" texrepeat="2 2" texture="texplane" texuniform="true" />
        
        <texture file="/home/martina/dexmv-sim/hand_imitation/env/models/assets/arenas/../textures/ceramic.png" name="tex-ceramic" type="cube" />
        <material name="table_ceramic" reflectance="0.0" shininess="0.0" specular="0.2" texrepeat="1 1" texture="tex-ceramic" />
        
        <texture file="/home/martina/dexmv-sim/hand_imitation/env/models/assets/arenas/../textures/steel-brushed.png" name="tex-steel-brushed" type="cube" />
        <material name="table_legs_metal" reflectance="0.8" shininess="0.8" texrepeat="1 1" texture="tex-steel-brushed" />
        
        <texture file="/home/martina/dexmv-sim/hand_imitation/env/models/assets/arenas/../textures/cream-plaster.png" name="tex-cream-plaster" type="2d" />
        <material name="walls_mat" reflectance="0.0" shininess="0.1" specular="0.1" texrepeat="3 3" texture="tex-cream-plaster" texuniform="true" />
        
        <texture builtin="flat" height="512" name="textable" rgb1="0.5 0.5 0.5" rgb2="0.5 0.5 0.5" width="512" />
        <material name="table_mat" texture="textable" />
    <mesh file="/home/martina/dexmv-sim/hand_imitation/env/utils/../models/assets/ycb/collision/025_mug/v0/025_mug_1.stl" name="mug_collision_mesh_1" scale="0.8 0.8 0.8" /><mesh file="/home/martina/dexmv-sim/hand_imitation/env/utils/../models/assets/ycb/collision/025_mug/v0/025_mug_10.stl" name="mug_collision_mesh_2" scale="0.8 0.8 0.8" /><mesh file="/home/martina/dexmv-sim/hand_imitation/env/utils/../models/assets/ycb/collision/025_mug/v0/025_mug_11.stl" name="mug_collision_mesh_3" scale="0.8 0.8 0.8" /><mesh file="/home/martina/dexmv-sim/hand_imitation/env/utils/../models/assets/ycb/collision/025_mug/v0/025_mug_12.stl" name="mug_collision_mesh_4" scale="0.8 0.8 0.8" /><mesh file="/home/martina/dexmv-sim/hand_imitation/env/utils/../models/assets/ycb/collision/025_mug/v0/025_mug_13.stl" name="mug_collision_mesh_5" scale="0.8 0.8 0.8" /><mesh file="/home/martina/dexmv-sim/hand_imitation/env/utils/../models/assets/ycb/collision/025_mug/v0/025_mug_14.stl" name="mug_collision_mesh_6" scale="0.8 0.8 0.8" /><mesh file="/home/martina/dexmv-sim/hand_imitation/env/utils/../models/assets/ycb/collision/025_mug/v0/025_mug_15.stl" name="mug_collision_mesh_7" scale="0.8 0.8 0.8" /><mesh file="/home/martina/dexmv-sim/hand_imitation/env/utils/../models/assets/ycb/collision/025_mug/v0/025_mug_16.stl" name="mug_collision_mesh_8" scale="0.8 0.8 0.8" /><mesh file="/home/martina/dexmv-sim/hand_imitation/env/utils/../models/assets/ycb/collision/025_mug/v0/025_mug_17.stl" name="mug_collision_mesh_9" scale="0.8 0.8 0.8" /><mesh file="/home/martina/dexmv-sim/hand_imitation/env/utils/../models/assets/ycb/collision/025_mug/v0/025_mug_18.stl" name="mug_collision_mesh_10" scale="0.8 0.8 0.8" /><mesh file="/home/martina/dexmv-sim/hand_imitation/env/utils/../models/assets/ycb/collision/025_mug/v0/025_mug_19.stl" name="mug_collision_mesh_11" scale="0.8 0.8 0.8" /><mesh file="/home/martina/dexmv-sim/hand_imitation/env/utils/../models/assets/ycb/collision/025_mug/v0/025_mug_2.stl" name="mug_collision_mesh_12" scale="0.8 0.8 0.8" /><mesh file="/home/martina/dexmv-sim/hand_imitation/env/utils/../models/assets/ycb/collision/025_mug/v0/025_mug_20.stl" name="mug_collision_mesh_13" scale="0.8 0.8 0.8" /><mesh file="/home/martina/dexmv-sim/hand_imitation/env/utils/../models/assets/ycb/collision/025_mug/v0/025_mug_21.stl" name="mug_collision_mesh_14" scale="0.8 0.8 0.8" /><mesh file="/home/martina/dexmv-sim/hand_imitation/env/utils/../models/assets/ycb/collision/025_mug/v0/025_mug_22.stl" name="mug_collision_mesh_15" scale="0.8 0.8 0.8" /><mesh file="/home/martina/dexmv-sim/hand_imitation/env/utils/../models/assets/ycb/collision/025_mug/v0/025_mug_23.stl" name="mug_collision_mesh_16" scale="0.8 0.8 0.8" /><mesh file="/home/martina/dexmv-sim/hand_imitation/env/utils/../models/assets/ycb/collision/025_mug/v0/025_mug_24.stl" name="mug_collision_mesh_17" scale="0.8 0.8 0.8" /><mesh file="/home/martina/dexmv-sim/hand_imitation/env/utils/../models/assets/ycb/collision/025_mug/v0/025_mug_25.stl" name="mug_collision_mesh_18" scale="0.8 0.8 0.8" /><mesh file="/home/martina/dexmv-sim/hand_imitation/env/utils/../models/assets/ycb/collision/025_mug/v0/025_mug_26.stl" name="mug_collision_mesh_19" scale="0.8 0.8 0.8" /><mesh file="/home/martina/dexmv-sim/hand_imitation/env/utils/../models/assets/ycb/collision/025_mug/v0/025_mug_27.stl" name="mug_collision_mesh_20" scale="0.8 0.8 0.8" /><mesh file="/home/martina/dexmv-sim/hand_imitation/env/utils/../models/assets/ycb/collision/025_mug/v0/025_mug_28.stl" name="mug_collision_mesh_21" scale="0.8 0.8 0.8" /><mesh file="/home/martina/dexmv-sim/hand_imitation/env/utils/../models/assets/ycb/collision/025_mug/v0/025_mug_29.stl" name="mug_collision_mesh_22" scale="0.8 0.8 0.8" /><mesh file="/home/martina/dexmv-sim/hand_imitation/env/utils/../models/assets/ycb/collision/025_mug/v0/025_mug_3.stl" name="mug_collision_mesh_23" scale="0.8 0.8 0.8" /><mesh file="/home/martina/dexmv-sim/hand_imitation/env/utils/../models/assets/ycb/collision/025_mug/v0/025_mug_30.stl" name="mug_collision_mesh_24" scale="0.8 0.8 0.8" /><mesh file="/home/martina/dexmv-sim/hand_imitation/env/utils/../models/assets/ycb/collision/025_mug/v0/025_mug_31.stl" name="mug_collision_mesh_25" scale="0.8 0.8 0.8" /><mesh file="/home/martina/dexmv-sim/hand_imitation/env/utils/../models/assets/ycb/collision/025_mug/v0/025_mug_32.stl" name="mug_collision_mesh_26" scale="0.8 0.8 0.8" /><mesh file="/home/martina/dexmv-sim/hand_imitation/env/utils/../models/assets/ycb/collision/025_mug/v0/025_mug_33.stl" name="mug_collision_mesh_27" scale="0.8 0.8 0.8" /><mesh file="/home/martina/dexmv-sim/hand_imitation/env/utils/../models/assets/ycb/collision/025_mug/v0/025_mug_34.stl" name="mug_collision_mesh_28" scale="0.8 0.8 0.8" /><mesh file="/home/martina/dexmv-sim/hand_imitation/env/utils/../models/assets/ycb/collision/025_mug/v0/025_mug_35.stl" name="mug_collision_mesh_29" scale="0.8 0.8 0.8" /><mesh file="/home/martina/dexmv-sim/hand_imitation/env/utils/../models/assets/ycb/collision/025_mug/v0/025_mug_36.stl" name="mug_collision_mesh_30" scale="0.8 0.8 0.8" /><mesh file="/home/martina/dexmv-sim/hand_imitation/env/utils/../models/assets/ycb/collision/025_mug/v0/025_mug_37.stl" name="mug_collision_mesh_31" scale="0.8 0.8 0.8" /><mesh file="/home/martina/dexmv-sim/hand_imitation/env/utils/../models/assets/ycb/collision/025_mug/v0/025_mug_38.stl" name="mug_collision_mesh_32" scale="0.8 0.8 0.8" /><mesh file="/home/martina/dexmv-sim/hand_imitation/env/utils/../models/assets/ycb/collision/025_mug/v0/025_mug_39.stl" name="mug_collision_mesh_33" scale="0.8 0.8 0.8" /><mesh file="/home/martina/dexmv-sim/hand_imitation/env/utils/../models/assets/ycb/collision/025_mug/v0/025_mug_4.stl" name="mug_collision_mesh_34" scale="0.8 0.8 0.8" /><mesh file="/home/martina/dexmv-sim/hand_imitation/env/utils/../models/assets/ycb/collision/025_mug/v0/025_mug_40.stl" name="mug_collision_mesh_35" scale="0.8 0.8 0.8" /><mesh file="/home/martina/dexmv-sim/hand_imitation/env/utils/../models/assets/ycb/collision/025_mug/v0/025_mug_41.stl" name="mug_collision_mesh_36" scale="0.8 0.8 0.8" /><mesh file="/home/martina/dexmv-sim/hand_imitation/env/utils/../models/assets/ycb/collision/025_mug/v0/025_mug_42.stl" name="mug_collision_mesh_37" scale="0.8 0.8 0.8" /><mesh file="/home/martina/dexmv-sim/hand_imitation/env/utils/../models/assets/ycb/collision/025_mug/v0/025_mug_43.stl" name="mug_collision_mesh_38" scale="0.8 0.8 0.8" /><mesh file="/home/martina/dexmv-sim/hand_imitation/env/utils/../models/assets/ycb/collision/025_mug/v0/025_mug_44.stl" name="mug_collision_mesh_39" scale="0.8 0.8 0.8" /><mesh file="/home/martina/dexmv-sim/hand_imitation/env/utils/../models/assets/ycb/collision/025_mug/v0/025_mug_45.stl" name="mug_collision_mesh_40" scale="0.8 0.8 0.8" /><mesh file="/home/martina/dexmv-sim/hand_imitation/env/utils/../models/assets/ycb/collision/025_mug/v0/025_mug_46.stl" name="mug_collision_mesh_41" scale="0.8 0.8 0.8" /><mesh file="/home/martina/dexmv-sim/hand_imitation/env/utils/../models/assets/ycb/collision/025_mug/v0/025_mug_47.stl" name="mug_collision_mesh_42" scale="0.8 0.8 0.8" /><mesh file="/home/martina/dexmv-sim/hand_imitation/env/utils/../models/assets/ycb/collision/025_mug/v0/025_mug_48.stl" name="mug_collision_mesh_43" scale="0.8 0.8 0.8" /><mesh file="/home/martina/dexmv-sim/hand_imitation/env/utils/../models/assets/ycb/collision/025_mug/v0/025_mug_49.stl" name="mug_collision_mesh_44" scale="0.8 0.8 0.8" /><mesh file="/home/martina/dexmv-sim/hand_imitation/env/utils/../models/assets/ycb/collision/025_mug/v0/025_mug_5.stl" name="mug_collision_mesh_45" scale="0.8 0.8 0.8" /><mesh file="/home/martina/dexmv-sim/hand_imitation/env/utils/../models/assets/ycb/collision/025_mug/v0/025_mug_6.stl" name="mug_collision_mesh_46" scale="0.8 0.8 0.8" /><mesh file="/home/martina/dexmv-sim/hand_imitation/env/utils/../models/assets/ycb/collision/025_mug/v0/025_mug_7.stl" name="mug_collision_mesh_47" scale="0.8 0.8 0.8" /><mesh file="/home/martina/dexmv-sim/hand_imitation/env/utils/../models/assets/ycb/collision/025_mug/v0/025_mug_8.stl" name="mug_collision_mesh_48" scale="0.8 0.8 0.8" /><mesh file="/home/martina/dexmv-sim/hand_imitation/env/utils/../models/assets/ycb/collision/025_mug/v0/025_mug_9.stl" name="mug_collision_mesh_49" scale="0.8 0.8 0.8" /><mesh file="/home/martina/dexmv-sim/hand_imitation/env/utils/../models/assets/ycb/visual/025_mug/textured_simple_blender.msh" name="mug_visual_mesh" scale="0.8 0.8 0.8" /><texture file="/home/martina/dexmv-sim/hand_imitation/env/utils/../models/assets/ycb/visual/025_mug/texture_map.png" name="mug_texture" type="2d" /><material name="mug_material" texture="mug_texture" /></asset>
  <worldbody>
    <body name="forearm" pos="0 -0.7 0.2" quat="0.000563312 -0.000562864 0.706825 0.707388">
      <inertial diaginertia="0.01 0.01 0.0075" mass="4" pos="0.001 -0.002 0.29" quat="0.982037 -0.0160006 0 -0.188007" />
      <joint armature="0.001" axis="1 0 0" damping="20" frictionloss="0.001" limited="true" margin="0.01" name="ARTx" pos="0 0 0" range="-0.25 0.25" type="slide" />
      <joint armature="0.001" axis="0 1 0" damping="20" frictionloss="0.001" limited="true" margin="0.01" name="ARTy" pos="0 0 0" range="0 0.2" type="slide" />
      <joint armature="0.001" axis="0 0 1" damping="20" frictionloss="0.001" limited="true" margin="0.01" name="ARTz" pos="0 0 0" range="-0.3 0.5" type="slide" />
      <joint armature="0.001" axis="1 0 0" damping="20" frictionloss="0.001" limited="true" margin="0.01" name="ARRx" pos="0 0 0" range="-0.75 0.75" />
      <joint armature="0.001" axis="0 1 0" damping="20" frictionloss="0.001" limited="true" margin="0.01" name="ARRy" pos="0 0 0" range="-0.75 0.75" />
      <joint armature="0.001" axis="0 0 1" damping="20" frictionloss="0.001" limited="true" margin="0.01" name="ARRz" pos="0 0 0" range="-0.75 0.75" />
      <geom conaffinity="0" contype="0" friction="1 0.5 0.01" group="1" margin="0.0005" material="MatViz" mesh="forearm_simple" name="V_forearm" pos="0 -0.01 0.181" quat="0.707388 0 0 -0.706825" type="mesh" />
      <geom conaffinity="0" friction="1 0.5 0.01" group="4" margin="0.0005" material="MatColl" name="C_forearm1" pos="0 0 0.29" rgba="0.4 0.5 0.6 0.1" size="0.06 0.043" type="capsule" />
      <body name="wrist" pos="0 0 0.396">
        <inertial diaginertia="0.001 0.001 0.001" mass="0.3" pos="0.003 0 0.016" quat="0.504234 0.49623 0.49523 0.504234" />
        <joint armature="0.005" axis="0 1 0" damping="0.5" frictionloss="0.001" limited="true" margin="0.01" name="WRJ1" pos="0 0 0" range="-0.524 0.175" user="1123" />
        <geom conaffinity="0" contype="0" friction="1 0.5 0.01" group="1" margin="0.0005" material="MatViz" mesh="wrist" name="V_wrist" type="mesh" />
                <geom conaffinity="0" friction="1 0.5 0.01" group="4" margin="0.0005" material="MatColl" name="C_wrist" quat="0.707107 0.707107 0 0" rgba="0.4 0.5 0.6 0.1" size="0.015 0.01" type="capsule" />
        <body name="palm" pos="0 0 0.034">
          <inertial diaginertia="0.001 0.001 0.001" mass="0.3" pos="0.006 0 0.036" quat="0.715833 0.0439898 0.0749825 0.692839" />
          <joint armature="0.001" axis="1 0 0" damping="0.05" frictionloss="0.001" limited="true" margin="0.01" name="WRJ0" pos="0 0 0" range="-0.785 0.611" user="1122" />
          <geom conaffinity="0" contype="0" friction="1 0.5 0.01" group="1" margin="0.0005" material="MatViz" mesh="palm" name="V_palm" type="mesh" />
          <geom conaffinity="0" friction="1 0.5 0.01" group="4" margin="0.0005" material="MatColl" name="C_palm0" pos="-0.008 0 0.038" rgba="0.4 0.5 0.6 0.1" size="0.052 0.015 0.06" type="box" />
          
          
          <site name="S_grasp" pos="0.007 -0.05 0.07" quat="0.00863043 -0.595202 -0.00337281 -0.803523" rgba="0 0 0 0" size="0.01" />
          <site group="4" name="Tch_ffmetacarpal" pos="0.033 -0.008 0.078" rgba="0.8 0.8 0.8 0.15" size="0.009 0.004 0.006" type="box" />
          <site group="4" name="Tch_mfmetacarpal" pos="0.011 -0.008 0.074" rgba="0.8 0.8 0.8 0.15" size="0.009 0.004 0.014" type="box" />
          <site group="4" name="Tch_rfmetacarpal" pos="-0.011 -0.008 0.068" rgba="0.8 0.8 0.8 0.15" size="0.009 0.004 0.016" type="box" />
          <site group="4" name="Tch_thmetacarpal" pos="0.006 -0.008 0.042" quat="0.959662 0 0.281157 0" rgba="0.8 0.8 0.8 0.15" size="0.008 0.004 0.015" type="box" />
          <site group="4" name="Tch_palm" pos="-0.017 -0.008 0.024" quat="0.877583 0 -0.479426 0" rgba="0.8 0.8 0.8 0.15" size="0.012 0.004 0.016" type="box" />
          <body name="ffknuckle" pos="0.033 0 0.095">
            <inertial diaginertia="1e-05 1e-05 1e-05" mass="0.008" pos="0 0 0" quat="0.520062 0.854102 0.00600072 -0.00300036" />
            <joint armature="0.001" axis="0 1 0" damping="0.05" frictionloss="0.001" limited="true" margin="0.01" name="FFJ3" pos="0 0 0" range="-0.436 0.436" user="1103" />
            <geom conaffinity="0" contype="0" friction="1 0.5 0.01" group="1" margin="0.0005" material="MatViz" mesh="knuckle" name="V_ffknuckle" type="mesh" />
            <body name="ffproximal" pos="0 0 0">
              <inertial diaginertia="1e-05 1e-05 1e-05" mass="0.014" pos="0 0 0.023" quat="0.707095 -0.00400054 0.00400054 0.707095" />
              <joint armature="0.001" axis="1 0 0" damping="0.05" frictionloss="0.001" limited="true" margin="0.01" name="FFJ2" pos="0 0 0" range="0 1.571" user="1102" />
              <geom conaffinity="0" contype="0" friction="1 0.5 0.01" group="1" margin="0.0005" material="MatViz" mesh="F3" name="V_ffproximal" type="mesh" />
              <geom conaffinity="0" friction="1 0.5 0.01" group="4" margin="0.0005" material="MatColl" name="C_ffproximal" pos="0 0 0.0225" size="0.01 0.0225" type="capsule" />
              <site group="4" name="Tch_ffproximal" pos="0 -0.007 0.022" rgba="0.8 0.8 0.8 0.15" size="0.009 0.004 0.012" type="box" />
              <body name="ffmiddle" pos="0 0 0.045">
                <inertial diaginertia="1e-05 1e-05 1e-05" mass="0.012" pos="0 0 0.011" quat="0.707107 0 0 0.707107" />
                <joint armature="0.001" axis="1 0 0" damping="0.05" frictionloss="0.001" limited="true" margin="0.01" name="FFJ1" pos="0 0 0" range="0 1.571" user="1101" />
                <geom conaffinity="0" contype="0" friction="1 0.5 0.01" group="1" margin="0.0005" material="MatViz" mesh="F2" name="V_ffmiddle" type="mesh" />
                <geom conaffinity="0" friction="1 0.5 0.01" group="4" margin="0.0005" material="MatColl" name="C_ffmiddle" pos="0 0 0.0125" size="0.00805 0.0125" type="capsule" />
                <site group="4" name="Tch_ffmiddle" pos="0 -0.007 0.013" rgba="0.8 0.8 0.8 0.15" size="0.009 0.002 0.007" type="box" />
                <body name="ffdistal" pos="0 0 0.025">
                  <inertial diaginertia="1e-05 1e-05 1e-05" mass="0.01" pos="0 0 0.015" quat="0.7071 -0.00300043 0.00300043 0.7071" />
                  <joint armature="0.001" axis="1 0 0" damping="0.05" frictionloss="0.001" limited="true" margin="0.01" name="FFJ0" pos="0 0 0" range="0 1.571" user="1100" />
                  <geom conaffinity="0" contype="0" friction="1 0.5 0.01" group="1" margin="0.0005" material="MatViz" mesh="F1" name="V_ffdistal" pos="0 0 0.001" type="mesh" />
                  <geom conaffinity="0" condim="4" friction="1 0.5 0.01" group="4" margin="0.0005" material="MatColl" name="C_ffdistal" pos="0 0 0.012" size="0.00705 0.012" type="capsule" />
                  <site group="3" name="S_fftip" pos="0 0 0.026" rgba="0.4 0.9 0.4 1" size="0.005 0 0" />
                  <site group="4" name="Tch_fftip" pos="0 -0.004 0.018" rgba="0.8 0.8 0.8 0.15" size="0.009 0.004 0.013" type="box" />
                </body>
              </body>
            </body>
          </body>
          <body name="mfknuckle" pos="0.011 0 0.099">
            <inertial diaginertia="1e-05 1e-05 1e-05" mass="0.008" pos="0 0 0" quat="0.520062 0.854102 0.00600072 -0.00300036" />
            <joint armature="0.001" axis="0 1 0" damping="0.05" frictionloss="0.001" limited="true" margin="0.01" name="MFJ3" pos="0 0 0" range="-0.436 0.436" user="1107" />
            <geom conaffinity="0" contype="0" friction="1 0.5 0.01" group="1" margin="0.0005" material="MatViz" mesh="knuckle" name="V_mfknuckle" type="mesh" />
            <body name="mfproximal" pos="0 0 0">
              <inertial diaginertia="1e-05 1e-05 1e-05" mass="0.014" pos="0 0 0.023" quat="0.707095 -0.00400054 0.00400054 0.707095" />
              <joint armature="0.001" axis="1 0 0" damping="0.05" frictionloss="0.001" limited="true" margin="0.01" name="MFJ2" pos="0 0 0" range="0 1.571" user="1106" />
              <geom conaffinity="0" contype="0" friction="1 0.5 0.01" group="1" margin="0.0005" material="MatViz" mesh="F3" name="V_mfproximal" type="mesh" />
              <geom conaffinity="0" friction="1 0.5 0.01" group="4" margin="0.0005" material="MatColl" name="C_mfproximal" pos="0 0 0.0225" size="0.01 0.0225" type="capsule" />
              <site group="4" name="Tch_mfproximal" pos="0 -0.007 0.022" rgba="0.8 0.8 0.8 0.15" size="0.009 0.004 0.012" type="box" />
              <body name="mfmiddle" pos="0 0 0.045">
                <inertial diaginertia="1e-05 1e-05 1e-05" mass="0.012" pos="0 0 0.012" quat="0.707107 0 0 0.707107" />
                <joint armature="0.001" axis="1 0 0" damping="0.05" frictionloss="0.001" limited="true" margin="0.01" name="MFJ1" pos="0 0 0" range="0 1.571" user="1105" />
                <geom conaffinity="0" contype="0" friction="1 0.5 0.01" group="1" margin="0.0005" material="MatViz" mesh="F2" name="V_mfmiddle" type="mesh" />
                <geom conaffinity="0" friction="1 0.5 0.01" group="4" margin="0.0005" material="MatColl" name="C_mfmiddle" pos="0 0 0.0125" size="0.00805 0.0125" type="capsule" />
                <site group="4" name="Tch_mfmiddle" pos="0 -0.007 0.013" rgba="0.8 0.8 0.8 0.15" size="0.009 0.002 0.007" type="box" />
                <body name="mfdistal" pos="0 0 0.025">
                  <inertial diaginertia="1e-05 1e-05 1e-05" mass="0.01" pos="0 0 0.015" quat="0.7071 -0.00300043 0.00300043 0.7071" />
                  <joint armature="0.001" axis="1 0 0" damping="0.05" frictionloss="0.001" limited="true" margin="0.01" name="MFJ0" pos="0 0 0" range="0 1.571" user="1104" />
                  <geom conaffinity="0" contype="0" friction="1 0.5 0.01" group="1" margin="0.0005" material="MatViz" mesh="F1" name="V_mfdistal" type="mesh" />
                  <geom conaffinity="0" condim="4" friction="1 0.5 0.01" group="4" margin="0.0005" material="MatColl" name="C_mfdistal" pos="0 0 0.012" size="0.00705 0.012" type="capsule" />
                  <site group="3" name="S_mftip" pos="0 0 0.026" rgba="0.4 0.9 0.4 1" size="0.005 0 0" />
                  <site group="4" name="Tch_mftip" pos="0 -0.004 0.018" rgba="0.8 0.8 0.8 0.15" size="0.009 0.004 0.013" type="box" />
                </body>
              </body>
            </body>
          </body>
          <body name="rfknuckle" pos="-0.011 0 0.095">
            <inertial diaginertia="1e-05 1e-05 1e-05" mass="0.008" pos="0 0 0" quat="0.520062 0.854102 0.00600072 -0.00300036" />
            <joint armature="0.001" axis="0 1 0" damping="0.05" frictionloss="0.001" limited="true" margin="0.01" name="RFJ3" pos="0 0 0" range="-0.436 0.436" user="1111" />
            <geom conaffinity="0" contype="0" friction="1 0.5 0.01" group="1" margin="0.0005" material="MatViz" mesh="knuckle" name="V_rfknuckle" type="mesh" />
            <body name="rfproximal" pos="0 0 0">
              <inertial diaginertia="1e-05 1e-05 1e-05" mass="0.014" pos="0 0 0.023" quat="0.707095 -0.00400054 0.00400054 0.707095" />
              <joint armature="0.001" axis="1 0 0" damping="0.05" frictionloss="0.001" limited="true" margin="0.01" name="RFJ2" pos="0 0 0" range="0 1.571" user="1110" />
              <geom conaffinity="0" contype="0" friction="1 0.5 0.01" group="1" margin="0.0005" material="MatViz" mesh="F3" name="V_rfproximal" type="mesh" />
              <geom conaffinity="0" friction="1 0.5 0.01" group="4" margin="0.0005" material="MatColl" name="C_rfproximal" pos="0 0 0.0225" size="0.01 0.0225" type="capsule" />
              <site group="4" name="Tch_rfproximal" pos="0 -0.007 0.022" rgba="0.8 0.8 0.8 0.15" size="0.009 0.004 0.012" type="box" />
              <body name="rfmiddle" pos="0 0 0.045">
                <inertial diaginertia="1e-05 1e-05 1e-05" mass="0.012" pos="0 0 0.012" quat="0.707107 0 0 0.707107" />
                <joint armature="0.001" axis="1 0 0" damping="0.05" frictionloss="0.001" limited="true" margin="0.01" name="RFJ1" pos="0 0 0" range="0 1.571" user="1109" />
                <geom conaffinity="0" contype="0" friction="1 0.5 0.01" group="1" margin="0.0005" material="MatViz" mesh="F2" name="V_rfmiddle" type="mesh" />
                <geom conaffinity="0" friction="1 0.5 0.01" group="4" margin="0.0005" material="MatColl" name="C_rfmiddle" pos="0 0 0.0125" size="0.00805 0.0125" type="capsule" />
                <site group="4" name="Tch_rfmiddle" pos="0 -0.007 0.013" rgba="0.8 0.8 0.8 0.15" size="0.009 0.002 0.007" type="box" />
                <body name="rfdistal" pos="0 0 0.025">
                  <inertial diaginertia="1e-05 1e-05 1e-05" mass="0.01" pos="0 0 0.015" quat="0.7071 -0.00300043 0.00300043 0.7071" />
                  <joint armature="0.001" axis="1 0 0" damping="0.05" frictionloss="0.001" limited="true" margin="0.01" name="RFJ0" pos="0 0 0" range="0 1.571" user="1108" />
                  <geom conaffinity="0" contype="0" friction="1 0.5 0.01" group="1" margin="0.0005" material="MatViz" mesh="F1" name="V_rfdistal" pos="0 0 0.001" type="mesh" />
                  <geom conaffinity="0" condim="4" friction="1 0.5 0.01" group="4" margin="0.0005" material="MatColl" name="C_rfdistal" pos="0 0 0.012" size="0.00705 0.012" type="capsule" />
                  <site group="3" name="S_rftip" pos="0 0 0.026" rgba="0.4 0.9 0.4 1" size="0.005 0 0" />
                  <site group="4" name="Tch_rftip" pos="0 -0.004 0.018" rgba="0.8 0.8 0.8 0.15" size="0.009 0.004 0.013" type="box" />
                </body>
              </body>
            </body>
          </body>
          <body name="lfmetacarpal" pos="-0.017 0 0.044">
            <inertial diaginertia="1e-05 1e-05 1e-05" mass="0.075" pos="-0.014 0.001 0.014" quat="0.709167 -0.0920216 -0.0630148 0.696164" />
            <joint armature="0.001" axis="0.570977 0 0.820966" damping="0.05" frictionloss="0.001" limited="true" margin="0.01" name="LFJ4" pos="0 0 0" range="0 0.698" user="1116" />
            <geom conaffinity="0" contype="0" friction="1 0.5 0.01" group="1" margin="0.0005" material="MatViz" mesh="lfmetacarpal" name="V_lfmetacarpal" pos="-0.016 0 -0.023" type="mesh" />
            
            
            <site group="4" name="Tch_lfmetacarpal" pos="-0.016 -0.008 0.017" rgba="0.8 0.8 0.8 0.15" size="0.009 0.004 0.014" type="box" />
            <body name="lfknuckle" pos="-0.017 0 0.044">
              <inertial diaginertia="1e-05 1e-05 1e-05" mass="0.008" pos="0 0 0" quat="0.520062 0.854102 0.00600072 -0.00300036" />
              <joint armature="0.001" axis="0 1 0" damping="0.05" frictionloss="0.001" limited="true" margin="0.01" name="LFJ3" pos="0 0 0" range="-0.436 0.436" user="1115" />
              <geom conaffinity="0" contype="0" friction="1 0.5 0.01" group="1" margin="0.0005" material="MatViz" mesh="knuckle" name="V_lfknuckle" type="mesh" />
              <body name="lfproximal" pos="0 0 0">
                <inertial diaginertia="1e-05 1e-05 1e-05" mass="0.014" pos="0 0 0.023" quat="0.707095 -0.00400054 0.00400054 0.707095" />
                <joint armature="0.001" axis="1 0 0" damping="0.05" frictionloss="0.001" limited="true" margin="0.01" name="LFJ2" pos="0 0 0" range="0 1.571" user="1114" />
                <geom conaffinity="0" contype="0" friction="1 0.5 0.01" group="1" margin="0.0005" material="MatViz" mesh="F3" name="V_lfproximal" type="mesh" />
                <geom conaffinity="0" friction="1 0.5 0.01" group="4" margin="0.0005" material="MatColl" name="C_lfproximal" pos="0 0 0.0225" size="0.01 0.0225" type="capsule" />
                <site group="4" name="Tch_lfproximal" pos="0 -0.007 0.022" rgba="0.8 0.8 0.8 0.15" size="0.009 0.004 0.012" type="box" />
                <body name="lfmiddle" pos="0 0 0.045">
                  <inertial diaginertia="1e-05 1e-05 1e-05" mass="0.012" pos="0 0 0.012" quat="0.707107 0 0 0.707107" />
                  <joint armature="0.001" axis="1 0 0" damping="0.05" frictionloss="0.001" limited="true" margin="0.01" name="LFJ1" pos="0 0 0" range="0 1.571" user="1113" />
                  <geom conaffinity="0" contype="0" friction="1 0.5 0.01" group="1" margin="0.0005" material="MatViz" mesh="F2" name="V_lfmiddle" type="mesh" />
                  <geom conaffinity="0" friction="1 0.5 0.01" group="4" margin="0.0005" material="MatColl" name="C_lfmiddle" pos="0 0 0.0125" size="0.00805 0.0125" type="capsule" />
                  <site group="4" name="Tch_lfmiddle" pos="0 -0.007 0.013" rgba="0.8 0.8 0.8 0.15" size="0.009 0.002 0.007" type="box" />
                  <body name="lfdistal" pos="0 0 0.025">
                    <inertial diaginertia="1e-05 1e-05 1e-05" mass="0.01" pos="0 0 0.015" quat="0.7071 -0.00300043 0.00300043 0.7071" />
                    <joint armature="0.001" axis="1 0 0" damping="0.05" frictionloss="0.001" limited="true" margin="0.01" name="LFJ0" pos="0 0 0" range="0 1.571" user="1112" />
                    <geom conaffinity="0" contype="0" friction="1 0.5 0.01" group="1" margin="0.0005" material="MatViz" mesh="F1" name="V_lfdistal" pos="0 0 0.001" type="mesh" />
                    <geom conaffinity="0" condim="4" friction="1 0.5 0.01" group="4" margin="0.0005" material="MatColl" name="C_lfdistal" pos="0 0 0.012" size="0.00705 0.012" type="capsule" />
                    <site group="3" name="S_lftip" pos="0 0 0.026" rgba="0.4 0.9 0.4 1" size="0.005 0 0" />
                    <site group="4" name="Tch_lftip" pos="0 -0.004 0.018" rgba="0.8 0.8 0.8 0.15" size="0.009 0.004 0.013" type="box" />
                  </body>
                </body>
              </body>
            </body>
          </body>
          <body name="thbase" pos="0.034 -0.009 0.029" quat="0.923956 0 0.382499 0">
            <inertial diaginertia="1e-05 1e-05 1e-05" mass="0.01" pos="0 0 0" />
            <joint armature="0.001" axis="0 0 -1" damping="0.05" frictionloss="0.001" limited="true" margin="0.01" name="THJ4" pos="0 0 0" range="-1.047 1.047" user="1121" />
            <geom group="1" name="V_thbase" size="0.001 0.001 0.001" type="box" />
            <body name="thproximal" pos="0 0 0">
              <inertial diaginertia="1e-05 1e-05 1e-05" mass="0.016" pos="0 0 0.017" quat="0.981604 0 0.000999597 0.190923" />
              <joint armature="0.001" axis="1 0 0" damping="0.05" frictionloss="0.001" limited="true" margin="0.01" name="THJ3" pos="0 0 0" range="0 1.309" user="1120" />
              <geom conaffinity="0" contype="0" friction="1 0.5 0.01" group="1" margin="0.0005" material="MatViz" mesh="TH3_z" name="V_thproximal" type="mesh" />
              <geom conaffinity="0" friction="1 0.5 0.01" group="4" margin="0.0005" material="MatColl" name="C_thproximal" pos="0 0 0.019" rgba="0.4 0.5 0.6 0.1" size="0.013 0.019" type="capsule" />
              <site group="4" name="Tch_thproximal" pos="-0.008 0 0.022" rgba="0.8 0.8 0.8 0.15" size="0.005 0.011 0.011" type="box" />
              <body name="thhub" pos="0 0 0.038">
                <inertial diaginertia="1e-05 1e-05 1e-05" mass="0.002" pos="0 0 0" />
                <joint armature="0.001" axis="1 0 0" damping="0.05" frictionloss="0.001" limited="true" margin="0.01" name="THJ2" pos="0 0 0" range="-0.262 0.262" user="1119" />
                <geom group="1" name="V_thhub" size="0.001 0.001 0.001" type="box" />
                <body name="thmiddle" pos="0 0 0">
                  <inertial diaginertia="1e-05 1e-05 1e-05" mass="0.016" pos="0 0 0.016" quat="0.999971 -0.000999971 -0.00699979 0.00299991" />
                  <joint armature="0.001" axis="0 1 0" damping="0.05" frictionloss="0.001" limited="true" margin="0.01" name="THJ1" pos="0 0 0" range="-0.524 0.524" user="1118" />
                  <geom conaffinity="0" contype="0" friction="1 0.5 0.01" group="1" margin="0.0005" material="MatViz" mesh="TH2_z" name="V_thmiddle" type="mesh" />
                  <geom conaffinity="0" friction="1 0.5 0.01" group="4" margin="0.0005" material="MatColl" name="C_thmiddle" pos="0 0 0.016" size="0.011 0.016" type="capsule" />
                  <site group="4" name="Tch_thmiddle" pos="-0.008 0 0.018" rgba="0.8 0.8 0.8 0.15" size="0.005 0.011 0.011" type="box" />
                  <body name="thdistal" pos="0 0 0.032">
                    <inertial diaginertia="1e-05 1e-05 1e-05" mass="0.016" pos="0 0 0.016" quat="0.99887 -0.00499935 -0.0469939 0.00499935" />
                    <joint armature="0.001" axis="0 1 0" damping="0.05" frictionloss="0.001" limited="true" margin="0.01" name="THJ0" pos="0 0 0" range="-1.571 0" user="1117" />
                    <geom conaffinity="0" contype="0" friction="1 0.5 0.01" group="1" margin="0.0005" material="MatViz" mesh="TH1_z" name="V_thdistal" type="mesh" />
                    <geom conaffinity="0" condim="4" friction="1 0.5 0.01" group="4" margin="0.0005" material="MatColl" name="C_thdistal" pos="0 0 0.013" size="0.00918 0.013" type="capsule" />
                    <site group="3" name="S_thtip" pos="0 0 0.0275" rgba="0.4 0.9 0.4 1" size="0.005 0 0" />
                    <site group="4" name="Tch_thtip" pos="-0.005 0 0.02" rgba="0.8 0.8 0.8 0.15" size="0.005 0.011 0.016" type="box" />
                  </body>
                </body>
              </body>
            </body>
          </body>
        </body>
      </body>
    </body>
  <geom condim="3" material="floorplane" name="floor" pos="0 0 -1" size="1.5 1.5 .125" type="plane" />
        
        <body name="table" pos="0.0 0.0 -0.025000000000000022">
            <geom friction="1 0.5 0.01" group="2" name="table_collision" pos="0 0 0" rgba="0.5 0.5 0 1" size="0.6 0.6 0.025" type="box" />
            <geom conaffinity="0" contype="0" group="1" material="table_ceramic" name="table_visual" pos="0 0 0" size="0.6 0.6 0.025" type="box" />
            <site name="table_top" pos="0.0 0.0 0.025" rgba="0 0 0 0" size="0.001 0.001 0.001" />
            
            <geom conaffinity="0" contype="0" group="1" material="table_legs_metal" name="table_leg1_visual" pos="0.5 0.5 -0.4875" size="0.025 0.4875" type="cylinder" />
            <geom conaffinity="0" contype="0" group="1" material="table_legs_metal" name="table_leg2_visual" pos="-0.5 0.5 -0.4875" size="0.025 0.4875" type="cylinder" />
            <geom conaffinity="0" contype="0" group="1" material="table_legs_metal" name="table_leg3_visual" pos="-0.5 -0.5 -0.4875" size="0.025 0.4875" type="cylinder" />
            <geom conaffinity="0" contype="0" group="1" material="table_legs_metal" name="table_leg4_visual" pos="0.5 -0.5 -0.4875" size="0.025 0.4875" type="cylinder" />
        </body>

        <light castshadow="false" diffuse=".8 .8 .8" dir="0 -.15 -1" directional="false" name="light1" pos="1 1 4.0" specular="0.3 0.3 0.3" />
        <light castshadow="false" diffuse=".8 .8 .8" dir="0 -.15 -1" directional="false" name="light2" pos="-3. -3. 4.0" specular="0.3 0.3 0.3" />
        <camera mode="fixed" name="zeroview" pos="0 0 0" quat="0 1 0 0" />
        <camera mode="fixed" name="frontview" pos="0 -1 0.9" quat="0.65 0.2705981, 0.2705981, 0.6532815" />
        <camera mode="fixed" name="backview" pos="0 0.6 0.9" quat="0 0 0.2815 0.9595" />
        <camera mode="fixed" name="sideview" pos="-1.3 -0.5 0.5" quat=" 0.6781121 0.5164697 -0.3290275 -0.4064037" />
    <body name="mug_0" pos="0 0 0.04065" quat="0.707 0 0 0.707"><geom condim="4" density="1000" friction="1 0.5 0.01" group="2" margin="0.003" mesh="mug_collision_mesh_1" name="collision_mug_1" type="mesh" /><geom condim="4" density="1000" friction="1 0.5 0.01" group="2" margin="0.003" mesh="mug_collision_mesh_2" name="collision_mug_2" type="mesh" /><geom condim="4" density="1000" friction="1 0.5 0.01" group="2" margin="0.003" mesh="mug_collision_mesh_3" name="collision_mug_3" type="mesh" /><geom condim="4" density="1000" friction="1 0.5 0.01" group="2" margin="0.003" mesh="mug_collision_mesh_4" name="collision_mug_4" type="mesh" /><geom condim="4" density="1000" friction="1 0.5 0.01" group="2" margin="0.003" mesh="mug_collision_mesh_5" name="collision_mug_5" type="mesh" /><geom condim="4" density="1000" friction="1 0.5 0.01" group="2" margin="0.003" mesh="mug_collision_mesh_6" name="collision_mug_6" type="mesh" /><geom condim="4" density="1000" friction="1 0.5 0.01" group="2" margin="0.003" mesh="mug_collision_mesh_7" name="collision_mug_7" type="mesh" /><geom condim="4" density="1000" friction="1 0.5 0.01" group="2" margin="0.003" mesh="mug_collision_mesh_8" name="collision_mug_8" type="mesh" /><geom condim="4" density="1000" friction="1 0.5 0.01" group="2" margin="0.003" mesh="mug_collision_mesh_9" name="collision_mug_9" type="mesh" /><geom condim="4" density="1000" friction="1 0.5 0.01" group="2" margin="0.003" mesh="mug_collision_mesh_10" name="collision_mug_10" type="mesh" /><geom condim="4" density="1000" friction="1 0.5 0.01" group="2" margin="0.003" mesh="mug_collision_mesh_11" name="collision_mug_11" type="mesh" /><geom condim="4" density="1000" friction="1 0.5 0.01" group="2" margin="0.003" mesh="mug_collision_mesh_12" name="collision_mug_12" type="mesh" /><geom condim="4" density="1000" friction="1 0.5 0.01" group="2" margin="0.003" mesh="mug_collision_mesh_13" name="collision_mug_13" type="mesh" /><geom condim="4" density="1000" friction="1 0.5 0.01" group="2" margin="0.003" mesh="mug_collision_mesh_14" name="collision_mug_14" type="mesh" /><geom condim="4" density="1000" friction="1 0.5 0.01" group="2" margin="0.003" mesh="mug_collision_mesh_15" name="collision_mug_15" type="mesh" /><geom condim="4" density="1000" friction="1 0.5 0.01" group="2" margin="0.003" mesh="mug_collision_mesh_16" name="collision_mug_16" type="mesh" /><geom condim="4" density="1000" friction="1 0.5 0.01" group="2" margin="0.003" mesh="mug_collision_mesh_17" name="collision_mug_17" type="mesh" /><geom condim="4" density="1000" friction="1 0.5 0.01" group="2" margin="0.003" mesh="mug_collision_mesh_18" name="collision_mug_18" type="mesh" /><geom condim="4" density="1000" friction="1 0.5 0.01" group="2" margin="0.003" mesh="mug_collision_mesh_19" name="collision_mug_19" type="mesh" /><geom condim="4" density="1000" friction="1 0.5 0.01" group="2" margin="0.003" mesh="mug_collision_mesh_20" name="collision_mug_20" type="mesh" /><geom condim="4" density="1000" friction="1 0.5 0.01" group="2" margin="0.003" mesh="mug_collision_mesh_21" name="collision_mug_21" type="mesh" /><geom condim="4" density="1000" friction="1 0.5 0.01" group="2" margin="0.003" mesh="mug_collision_mesh_22" name="collision_mug_22" type="mesh" /><geom condim="4" density="1000" friction="1 0.5 0.01" group="2" margin="0.003" mesh="mug_collision_mesh_23" name="collision_mug_23" type="mesh" /><geom condim="4" density="1000" friction="1 0.5 0.01" group="2" margin="0.003" mesh="mug_collision_mesh_24" name="collision_mug_24" type="mesh" /><geom condim="4" density="1000" friction="1 0.5 0.01" group="2" margin="0.003" mesh="mug_collision_mesh_25" name="collision_mug_25" type="mesh" /><geom condim="4" density="1000" friction="1 0.5 0.01" group="2" margin="0.003" mesh="mug_collision_mesh_26" name="collision_mug_26" type="mesh" /><geom condim="4" density="1000" friction="1 0.5 0.01" group="2" margin="0.003" mesh="mug_collision_mesh_27" name="collision_mug_27" type="mesh" /><geom condim="4" density="1000" friction="1 0.5 0.01" group="2" margin="0.003" mesh="mug_collision_mesh_28" name="collision_mug_28" type="mesh" /><geom condim="4" density="1000" friction="1 0.5 0.01" group="2" margin="0.003" mesh="mug_collision_mesh_29" name="collision_mug_29" type="mesh" /><geom condim="4" density="1000" friction="1 0.5 0.01" group="2" margin="0.003" mesh="mug_collision_mesh_30" name="collision_mug_30" type="mesh" /><geom condim="4" density="1000" friction="1 0.5 0.01" group="2" margin="0.003" mesh="mug_collision_mesh_31" name="collision_mug_31" type="mesh" /><geom condim="4" density="1000" friction="1 0.5 0.01" group="2" margin="0.003" mesh="mug_collision_mesh_32" name="collision_mug_32" type="mesh" /><geom condim="4" density="1000" friction="1 0.5 0.01" group="2" margin="0.003" mesh="mug_collision_mesh_33" name="collision_mug_33" type="mesh" /><geom condim="4" density="1000" friction="1 0.5 0.01" group="2" margin="0.003" mesh="mug_collision_mesh_34" name="collision_mug_34" type="mesh" /><geom condim="4" density="1000" friction="1 0.5 0.01" group="2" margin="0.003" mesh="mug_collision_mesh_35" name="collision_mug_35" type="mesh" /><geom condim="4" density="1000" friction="1 0.5 0.01" group="2" margin="0.003" mesh="mug_collision_mesh_36" name="collision_mug_36" type="mesh" /><geom condim="4" density="1000" friction="1 0.5 0.01" group="2" margin="0.003" mesh="mug_collision_mesh_37" name="collision_mug_37" type="mesh" /><geom condim="4" density="1000" friction="1 0.5 0.01" group="2" margin="0.003" mesh="mug_collision_mesh_38" name="collision_mug_38" type="mesh" /><geom condim="4" density="1000" friction="1 0.5 0.01" group="2" margin="0.003" mesh="mug_collision_mesh_39" name="collision_mug_39" type="mesh" /><geom condim="4" density="1000" friction="1 0.5 0.01" group="2" margin="0.003" mesh="mug_collision_mesh_40" name="collision_mug_40" type="mesh" /><geom condim="4" density="1000" friction="1 0.5 0.01" group="2" margin="0.003" mesh="mug_collision_mesh_41" name="collision_mug_41" type="mesh" /><geom condim="4" density="1000" friction="1 0.5 0.01" group="2" margin="0.003" mesh="mug_collision_mesh_42" name="collision_mug_42" type="mesh" /><geom condim="4" density="1000" friction="1 0.5 0.01" group="2" margin="0.003" mesh="mug_collision_mesh_43" name="collision_mug_43" type="mesh" /><geom condim="4" density="1000" friction="1 0.5 0.01" group="2" margin="0.003" mesh="mug_collision_mesh_44" name="collision_mug_44" type="mesh" /><geom condim="4" density="1000" friction="1 0.5 0.01" group="2" margin="0.003" mesh="mug_collision_mesh_45" name="collision_mug_45" type="mesh" /><geom condim="4" density="1000" friction="1 0.5 0.01" group="2" margin="0.003" mesh="mug_collision_mesh_46" name="collision_mug_46" type="mesh" /><geom condim="4" density="1000" friction="1 0.5 0.01" group="2" margin="0.003" mesh="mug_collision_mesh_47" name="collision_mug_47" type="mesh" /><geom condim="4" density="1000" friction="1 0.5 0.01" group="2" margin="0.003" mesh="mug_collision_mesh_48" name="collision_mug_48" type="mesh" /><geom condim="4" density="1000" friction="1 0.5 0.01" group="2" margin="0.003" mesh="mug_collision_mesh_49" name="collision_mug_49" type="mesh" /><geom conaffinity="0" contype="0" group="1" material="mug_material" mesh="mug_visual_mesh" type="mesh" /><joint armature="0.001" damping="0" frictionloss="0.001" limited="false" name="mug_joint_0" type="free" /></body><body name="target" pos="0.10845 0.0965 0.16065" quat="0.707 0 0 0.707"><geom conaffinity="0" contype="0" mesh="mug_visual_mesh" rgba="0 1 0 0.125" type="mesh" /></body></worldbody>
  <contact>
    <pair condim="1" geom1="C_palm0" geom2="C_thdistal" />
    <pair condim="1" geom1="C_ffproximal" geom2="C_mfproximal" />
    <pair condim="1" geom1="C_ffproximal" geom2="C_thdistal" />
    <pair condim="1" geom1="C_ffmiddle" geom2="C_thdistal" />
    <pair condim="1" geom1="C_ffdistal" geom2="C_mfdistal" />
    <pair condim="1" geom1="C_ffdistal" geom2="C_thdistal" />
    <pair condim="1" geom1="C_mfproximal" geom2="C_rfproximal" />
    <pair condim="1" geom1="C_mfproximal" geom2="C_thdistal" />
    <pair condim="1" geom1="C_mfdistal" geom2="C_rfdistal" />
    <pair condim="1" geom1="C_mfdistal" geom2="C_lfdistal" />
    <pair condim="1" geom1="C_mfdistal" geom2="C_thdistal" />
    <pair condim="1" geom1="C_rfproximal" geom2="C_lfproximal" />
    <pair condim="1" geom1="C_rfmiddle" geom2="C_lfmiddle" />
    <pair condim="1" geom1="C_rfmiddle" geom2="C_lfdistal" />
    <pair condim="1" geom1="C_rfdistal" geom2="C_lfmiddle" />
    <pair condim="1" geom1="C_rfdistal" geom2="C_lfdistal" />
    <pair condim="1" geom1="C_rfdistal" geom2="C_lfdistal" />
    <pair condim="1" geom1="C_rfdistal" geom2="C_thdistal" />
    <pair condim="1" geom1="C_lfdistal" geom2="C_thdistal" />
  </contact>
  <tendon>
    <fixed limited="true" name="T_WRJ1r" range="-0.032 0.032" user="1236">
      <joint coef="0.018" joint="WRJ1" />
    </fixed>
    <fixed limited="true" name="T_WRJ1l" range="-0.032 0.032" user="1237">
      <joint coef="-0.018" joint="WRJ1" />
    </fixed>
    <fixed limited="true" name="T_WRJ0u" range="-0.032 0.032" user="1236">
      <joint coef="0.018" joint="WRJ0" />
    </fixed>
    <fixed limited="true" name="T_WRJ0d" range="-0.032 0.032" user="1237">
      <joint coef="-0.018" joint="WRJ0" />
    </fixed>
    <fixed limited="true" name="T_FFJ3r" range="-0.018 0.018" user="1204">
      <joint coef="0.01" joint="FFJ3" />
    </fixed>
    <fixed limited="true" name="T_FFJ3l" range="-0.018 0.018" user="1205">
      <joint coef="-0.01" joint="FFJ3" />
    </fixed>
    <fixed limited="true" name="T_FFJ2u" range="-0.007 0.03" user="1202">
      <joint coef="0.01" joint="FFJ2" />
    </fixed>
    <fixed limited="true" name="T_FFJ2d" range="-0.03 0.007" user="1203">
      <joint coef="-0.01" joint="FFJ2" />
    </fixed>
    <fixed limited="true" name="T_FFJ1c" range="-0.001 0.001">
      <joint coef="0.00705" joint="FFJ0" />
      <joint coef="-0.00805" joint="FFJ1" />
    </fixed>
    <fixed limited="true" name="T_FFJ1u" range="-0.007 0.03" user="1200">
      <joint coef="0.00705" joint="FFJ0" />
      <joint coef="0.00805" joint="FFJ1" />
    </fixed>
    <fixed limited="true" name="T_FFJ1d" range="-0.03 0.007" user="1201">
      <joint coef="-0.00705" joint="FFJ0" />
      <joint coef="-0.00805" joint="FFJ1" />
    </fixed>
    <fixed limited="true" name="T_MFJ3r" range="-0.018 0.018" user="1210">
      <joint coef="0.01" joint="MFJ3" />
    </fixed>
    <fixed limited="true" name="T_MFJ3l" range="-0.018 0.018" user="1211">
      <joint coef="-0.01" joint="MFJ3" />
    </fixed>
    <fixed limited="true" name="T_MFJ2u" range="-0.007 0.03" user="1208">
      <joint coef="0.01" joint="MFJ2" />
    </fixed>
    <fixed limited="true" name="T_MFJ2d" range="-0.03 0.007" user="1209">
      <joint coef="-0.01" joint="MFJ2" />
    </fixed>
    <fixed limited="true" name="T_MFJ1c" range="-0.001 0.001">
      <joint coef="0.00705" joint="MFJ0" />
      <joint coef="-0.00805" joint="MFJ1" />
    </fixed>
    <fixed limited="true" name="T_MFJ1u" range="-0.007 0.03" user="1206">
      <joint coef="0.00705" joint="MFJ0" />
      <joint coef="0.00805" joint="MFJ1" />
    </fixed>
    <fixed limited="true" name="T_MFJ1d" range="-0.03 0.007" user="1207">
      <joint coef="-0.00705" joint="MFJ0" />
      <joint coef="-0.00805" joint="MFJ1" />
    </fixed>
    <fixed limited="true" name="T_RFJ3r" range="-0.018 0.018" user="1216">
      <joint coef="0.01" joint="RFJ3" />
    </fixed>
    <fixed limited="true" name="T_RFJ3l" range="-0.018 0.018" user="1217">
      <joint coef="-0.01" joint="RFJ3" />
    </fixed>
    <fixed limited="true" name="T_RFJ2u" range="-0.007 0.03" user="1214">
      <joint coef="0.01" joint="RFJ2" />
    </fixed>
    <fixed limited="true" name="T_RFJ2d" range="-0.03 0.007" user="1215">
      <joint coef="-0.01" joint="RFJ2" />
    </fixed>
    <fixed limited="true" name="T_RFJ1c" range="-0.001 0.001">
      <joint coef="0.00705" joint="RFJ0" />
      <joint coef="-0.00805" joint="RFJ1" />
    </fixed>
    <fixed limited="true" name="T_RFJ1u" range="-0.007 0.03" user="1212">
      <joint coef="0.00705" joint="RFJ0" />
      <joint coef="0.00805" joint="RFJ1" />
    </fixed>
    <fixed limited="true" name="T_RFJ1d" range="-0.03 0.007" user="1213">
      <joint coef="-0.00705" joint="RFJ0" />
      <joint coef="-0.00805" joint="RFJ1" />
    </fixed>
    <fixed limited="true" name="T_LFJ4u" range="-0.007 0.03" user="1224">
      <joint coef="0.01" joint="LFJ4" />
    </fixed>
    <fixed limited="true" name="T_LFJ4d" range="-0.03 0.007" user="1225">
      <joint coef="-0.01" joint="LFJ4" />
    </fixed>
    <fixed limited="true" name="T_LFJ3r" range="-0.018 0.018" user="1222">
      <joint coef="0.01" joint="LFJ3" />
    </fixed>
    <fixed limited="true" name="T_LFJ3l" range="-0.018 0.018" user="1223">
      <joint coef="-0.01" joint="LFJ3" />
    </fixed>
    <fixed limited="true" name="T_LFJ2u" range="-0.007 0.03" user="1220">
      <joint coef="0.01" joint="LFJ2" />
    </fixed>
    <fixed limited="true" name="T_LFJ2d" range="-0.03 0.007" user="1221">
      <joint coef="-0.01" joint="LFJ2" />
    </fixed>
    <fixed limited="true" name="T_LFJ1c" range="-0.001 0.001">
      <joint coef="0.00705" joint="LFJ0" />
      <joint coef="-0.00805" joint="LFJ1" />
    </fixed>
    <fixed limited="true" name="T_LFJ1u" range="-0.007 0.03" user="1218">
      <joint coef="0.00705" joint="LFJ0" />
      <joint coef="0.00805" joint="LFJ1" />
    </fixed>
    <fixed limited="true" name="T_LFJ1d" range="-0.03 0.007" user="1219">
      <joint coef="-0.00705" joint="LFJ0" />
      <joint coef="-0.00805" joint="LFJ1" />
    </fixed>
    <fixed limited="true" name="T_THJ4a" range="-0.018 0.018" user="1234">
      <joint coef="0.01636" joint="THJ4" />
    </fixed>
    <fixed limited="true" name="T_THJ4c" range="-0.018 0.018" user="1235">
      <joint coef="-0.01636" joint="THJ4" />
    </fixed>
    <fixed limited="true" name="T_THJ3u" range="-0.007 0.03" user="1232">
      <joint coef="0.01" joint="THJ3" />
    </fixed>
    <fixed limited="true" name="T_THJ3d" range="-0.03 0.007" user="1233">
      <joint coef="-0.01" joint="THJ3" />
    </fixed>
    <fixed limited="true" name="T_THJ2u" range="-0.018 0.018" user="1230">
      <joint coef="0.011" joint="THJ2" />
    </fixed>
    <fixed limited="true" name="T_THJ2d" range="-0.018 0.018" user="1231">
      <joint coef="-0.011" joint="THJ2" />
    </fixed>
    <fixed limited="true" name="T_THJ1r" range="-0.018 0.018" user="1228">
      <joint coef="0.011" joint="THJ1" />
    </fixed>
    <fixed limited="true" name="T_THJ1l" range="-0.018 0.018" user="1229">
      <joint coef="-0.011" joint="THJ1" />
    </fixed>
    <fixed limited="true" name="T_THJ0r" range="-0.03 0.007" user="1226">
      <joint coef="0.009" joint="THJ0" />
    </fixed>
    <fixed limited="true" name="T_THJ0l" range="-0.007 0.03" user="1227">
      <joint coef="-0.009" joint="THJ0" />
    </fixed>
  </tendon>
  <actuator>
    <general biasprm="0 -200 0 0 0 0 0 0 0 0" biastype="affine" ctrllimited="true" ctrlrange="-0.25 0.25" gainprm="500 0 0 0 0 0 0 0 0 0" joint="ARTx" name="A_ARTx" user="0 1 0.03 0.0939711 0.513477 0.0358776 1.23598 8.40409 0.485031 6.04244 1.02187 0.175297 0.121642 0 0 0" />
    <general biasprm="0 -200 0 0 0 0 0 0 0 0" biastype="affine" ctrllimited="true" ctrlrange="0 0.2" gainprm="500 0 0 0 0 0 0 0 0 0" joint="ARTy" name="A_ARTy" user="0 1 0.03 0.0939711 0.513477 0.0358776 1.23598 8.40409 0.485031 6.04244 1.02187 0.175297 0.121642 0 0 0" />
    <general biasprm="0 -200 0 0 0 0 0 0 0 0" biastype="affine" ctrllimited="true" ctrlrange="-0.3 0.5" gainprm="500 0 0 0 0 0 0 0 0 0" joint="ARTz" name="A_ARTz" user="0 1 0.03 0.0939711 0.513477 0.0358776 1.23598 8.40409 0.485031 6.04244 1.02187 0.175297 0.121642 0 0 0" />
    <general biasprm="0 -200 0 0 0 0 0 0 0 0" biastype="affine" ctrllimited="true" ctrlrange="-0.75 0.75" gainprm="500 0 0 0 0 0 0 0 0 0" joint="ARRx" name="A_ARRx" user="0 1 0.03 0.0939711 0.513477 0.0358776 1.23598 8.40409 0.485031 6.04244 1.02187 0.175297 0.121642 0 0 0" />
    <general biasprm="0 -200 0 0 0 0 0 0 0 0" biastype="affine" ctrllimited="true" ctrlrange="-0.75 0.75" gainprm="500 0 0 0 0 0 0 0 0 0" joint="ARRy" name="A_ARRy" user="0 1 0.03 0.0939711 0.513477 0.0358776 1.23598 8.40409 0.485031 6.04244 1.02187 0.175297 0.121642 0 0 0" />
    <general biasprm="0 -200 0 0 0 0 0 0 0 0" biastype="affine" ctrllimited="true" ctrlrange="-0.75 0.75" gainprm="500 0 0 0 0 0 0 0 0 0" joint="ARRz" name="A_ARRz" user="0 1 0.03 0.0939711 0.513477 0.0358776 1.23598 8.40409 0.485031 6.04244 1.02187 0.175297 0.121642 0 0 0" />
    <general biasprm="0 -10 0 0 0 0 0 0 0 0" biastype="affine" ctrllimited="true" ctrlrange="-0.524 0.175" gainprm="10 0 0 0 0 0 0 0 0 0" joint="WRJ1" name="A_WRJ1" user="1002 0 2001 -0.02 0.02 0 0 0 0 0 0 0 0 0 0 0" />
    <general biasprm="0 -10 0 0 0 0 0 0 0 0" biastype="affine" ctrllimited="true" ctrlrange="-0.79 0.61" gainprm="10 0 0 0 0 0 0 0 0 0" joint="WRJ0" name="A_WRJ0" user="1002 0 2001 -0.02 0.02 0 0 0 0 0 0 0 0 0 0 0" />
    <general biasprm="0 -1 0 0 0 0 0 0 0 0" biastype="affine" ctrllimited="true" ctrlrange="-0.44 0.44" joint="FFJ3" name="A_FFJ3" user="1002 0 2001 -0.1 0.1 0 0 0 0 0 0 0 0 0 0 0" />
    <general biasprm="0 -1 0 0 0 0 0 0 0 0" biastype="affine" ctrllimited="true" ctrlrange="0 1.6" joint="FFJ2" name="A_FFJ2" user="1002 0 2001 -0.1 0.1 0 0 0 0 0 0 0 0 0 0 0" />
    <general biasprm="0 -1 0 0 0 0 0 0 0 0" biastype="affine" ctrllimited="true" ctrlrange="0 1.6" joint="FFJ1" name="A_FFJ1" user="1002 0 2001 -0.1 0.1 0 0 0 0 0 0 0 0 0 0 0" />
    <general biasprm="0 -1 0 0 0 0 0 0 0 0" biastype="affine" ctrllimited="true" ctrlrange="0 1.6" joint="FFJ0" name="A_FFJ0" user="1002 0 2001 -0.1 0.1 0 0 0 0 0 0 0 0 0 0 0" />
    <general biasprm="0 -1 0 0 0 0 0 0 0 0" biastype="affine" ctrllimited="true" ctrlrange="-0.44 0.44" joint="MFJ3" name="A_MFJ3" user="1002 0 2001 -0.1 0.1 0 0 0 0 0 0 0 0 0 0 0" />
    <general biasprm="0 -1 0 0 0 0 0 0 0 0" biastype="affine" ctrllimited="true" ctrlrange="0 1.6" joint="MFJ2" name="A_MFJ2" user="1002 0 2001 -0.1 0.1 0 0 0 0 0 0 0 0 0 0 0" />
    <general biasprm="0 -1 0 0 0 0 0 0 0 0" biastype="affine" ctrllimited="true" ctrlrange="0 1.6" joint="MFJ1" name="A_MFJ1" user="1002 0 2001 -0.1 0.1 0 0 0 0 0 0 0 0 0 0 0" />
    <general biasprm="0 -1 0 0 0 0 0 0 0 0" biastype="affine" ctrllimited="true" ctrlrange="0 1.6" joint="MFJ0" name="A_MFJ0" user="1002 0 2001 -0.1 0.1 0 0 0 0 0 0 0 0 0 0 0" />
    <general biasprm="0 -1 0 0 0 0 0 0 0 0" biastype="affine" ctrllimited="true" ctrlrange="-0.44 0.44" joint="RFJ3" name="A_RFJ3" user="1002 0 2001 -0.1 0.1 0 0 0 0 0 0 0 0 0 0 0" />
    <general biasprm="0 -1 0 0 0 0 0 0 0 0" biastype="affine" ctrllimited="true" ctrlrange="0 1.6" joint="RFJ2" name="A_RFJ2" user="1002 0 2001 -0.1 0.1 0 0 0 0 0 0 0 0 0 0 0" />
    <general biasprm="0 -1 0 0 0 0 0 0 0 0" biastype="affine" ctrllimited="true" ctrlrange="0 1.6" joint="RFJ1" name="A_RFJ1" user="1002 0 2001 -0.1 0.1 0 0 0 0 0 0 0 0 0 0 0" />
    <general biasprm="0 -1 0 0 0 0 0 0 0 0" biastype="affine" ctrllimited="true" ctrlrange="0 1.6" joint="RFJ0" name="A_RFJ0" user="1002 0 2001 -0.1 0.1 0 0 0 0 0 0 0 0 0 0 0" />
    <general biasprm="0 -1 0 0 0 0 0 0 0 0" biastype="affine" ctrllimited="true" ctrlrange="0 0.7" joint="LFJ4" name="A_LFJ4" user="1002 0 2001 -0.1 0.1 0 0 0 0 0 0 0 0 0 0 0" />
    <general biasprm="0 -1 0 0 0 0 0 0 0 0" biastype="affine" ctrllimited="true" ctrlrange="-0.44 0.44" joint="LFJ3" name="A_LFJ3" user="1002 0 2001 -0.1 0.1 0 0 0 0 0 0 0 0 0 0 0" />
    <general biasprm="0 -1 0 0 0 0 0 0 0 0" biastype="affine" ctrllimited="true" ctrlrange="0 1.6" joint="LFJ2" name="A_LFJ2" user="1002 0 2001 -0.1 0.1 0 0 0 0 0 0 0 0 0 0 0" />
    <general biasprm="0 -1 0 0 0 0 0 0 0 0" biastype="affine" ctrllimited="true" ctrlrange="0 1.6" joint="LFJ1" name="A_LFJ1" user="1002 0 2001 -0.1 0.1 0 0 0 0 0 0 0 0 0 0 0" />
    <general biasprm="0 -1 0 0 0 0 0 0 0 0" biastype="affine" ctrllimited="true" ctrlrange="0 1.6" joint="LFJ0" name="A_LFJ0" user="1002 0 2001 -0.1 0.1 0 0 0 0 0 0 0 0 0 0 0" />
    <general biasprm="0 -1 0 0 0 0 0 0 0 0" biastype="affine" ctrllimited="true" ctrlrange="-1 1" joint="THJ4" name="A_THJ4" user="1002 0 2001 -0.1 0.1 0 0 0 0 0 0 0 0 0 0 0" />
    <general biasprm="0 -1 0 0 0 0 0 0 0 0" biastype="affine" ctrllimited="true" ctrlrange="0 1.3" joint="THJ3" name="A_THJ3" user="1002 0 2001 -0.1 0.1 0 0 0 0 0 0 0 0 0 0 0" />
    <general biasprm="0 -1 0 0 0 0 0 0 0 0" biastype="affine" ctrllimited="true" ctrlrange="-0.26 0.26" joint="THJ2" name="A_THJ2" user="1002 0 2001 -0.1 0.1 0 0 0 0 0 0 0 0 0 0 0" />
    <general biasprm="0 -1 0 0 0 0 0 0 0 0" biastype="affine" ctrllimited="true" ctrlrange="-0.52 0.52" joint="THJ1" name="A_THJ1" user="1002 0 2001 -0.1 0.1 0 0 0 0 0 0 0 0 0 0 0" />
    <general biasprm="0 -1 0 0 0 0 0 0 0 0" biastype="affine" ctrllimited="true" ctrlrange="-1.571 0" joint="THJ0" name="A_THJ0" user="1002 0 2001 -0.1 0.1 0 0 0 0 0 0 0 0 0 0 0" />
  </actuator>
  <sensor>
    <actuatorfrc actuator="A_WRJ1" name="Saf_A_WRJ1" />
    <actuatorfrc actuator="A_WRJ0" name="Saf_A_WRJ0" />
    <actuatorfrc actuator="A_FFJ3" name="Saf_A_FFJ3" />
    <actuatorfrc actuator="A_FFJ2" name="Saf_A_FFJ2" />
    <actuatorfrc actuator="A_FFJ1" name="Saf_A_FFJ1" />
    <actuatorfrc actuator="A_MFJ3" name="Saf_A_MFJ3" />
    <actuatorfrc actuator="A_MFJ2" name="Saf_A_MFJ2" />
    <actuatorfrc actuator="A_MFJ1" name="Saf_A_MFJ1" />
    <actuatorfrc actuator="A_RFJ3" name="Saf_A_RFJ3" />
    <actuatorfrc actuator="A_RFJ2" name="Saf_A_RFJ2" />
    <actuatorfrc actuator="A_RFJ1" name="Saf_A_RFJ1" />
    <actuatorfrc actuator="A_LFJ4" name="Saf_A_LFJ4" />
    <actuatorfrc actuator="A_LFJ3" name="Saf_A_LFJ3" />
    <actuatorfrc actuator="A_LFJ2" name="Saf_A_LFJ2" />
    <actuatorfrc actuator="A_LFJ1" name="Saf_A_LFJ1" />
    <actuatorfrc actuator="A_THJ4" name="Saf_A_THJ4" />
    <actuatorfrc actuator="A_THJ3" name="Saf_A_THJ3" />
    <actuatorfrc actuator="A_THJ2" name="Saf_A_THJ2" />
    <actuatorfrc actuator="A_THJ1" name="Saf_A_THJ1" />
    <actuatorfrc actuator="A_THJ0" name="Saf_A_THJ0" />
    <touch name="ST_Tch_fftip" site="Tch_fftip" />
    <touch name="ST_Tch_mftip" site="Tch_mftip" />
    <touch name="ST_Tch_rftip" site="Tch_rftip" />
    <touch name="ST_Tch_lftip" site="Tch_lftip" />
    <touch name="ST_Tch_thtip" site="Tch_thtip" />
    <touch name="ST_Tch_ffmiddle" site="Tch_ffmiddle" />
    <touch name="ST_Tch_mfmiddle" site="Tch_mfmiddle" />
    <touch name="ST_Tch_rfmiddle" site="Tch_rfmiddle" />
    <touch name="ST_Tch_lfmiddle" site="Tch_lfmiddle" />
    <touch name="ST_Tch_thmiddle" site="Tch_thmiddle" />
    <touch name="ST_Tch_ffproximal" site="Tch_ffproximal" />
    <touch name="ST_Tch_mfproximal" site="Tch_mfproximal" />
    <touch name="ST_Tch_rfproximal" site="Tch_rfproximal" />
    <touch name="ST_Tch_lfproximal" site="Tch_lfproximal" />
    <touch name="ST_Tch_thproximal" site="Tch_thproximal" />
    <touch name="ST_Tch_ffmetacarpal" site="Tch_ffmetacarpal" />
    <touch name="ST_Tch_mfmetacarpal" site="Tch_mfmetacarpal" />
    <touch name="ST_Tch_rfmetacarpal" site="Tch_rfmetacarpal" />
    <touch name="ST_Tch_lfmetacarpal" site="Tch_lfmetacarpal" />
    <touch name="ST_Tch_thmetacarpal" site="Tch_thmetacarpal" />
    <touch name="ST_Tch_palm" site="Tch_palm" />
    <jointpos joint="WRJ1" name="Sjp_WRJ1" />
    <jointpos joint="WRJ0" name="Sjp_WRJ0" />
    <jointpos joint="FFJ3" name="Sjp_FFJ3" />
    <jointpos joint="FFJ2" name="Sjp_FFJ2" />
    <jointpos joint="FFJ1" name="Sjp_FFJ1" />
    <jointpos joint="FFJ0" name="Sjp_FFJ0" />
    <jointpos joint="MFJ3" name="Sjp_MFJ3" />
    <jointpos joint="MFJ2" name="Sjp_MFJ2" />
    <jointpos joint="MFJ1" name="Sjp_MFJ1" />
    <jointpos joint="MFJ0" name="Sjp_MFJ0" />
    <jointpos joint="RFJ3" name="Sjp_RFJ3" />
    <jointpos joint="RFJ2" name="Sjp_RFJ2" />
    <jointpos joint="RFJ1" name="Sjp_RFJ1" />
    <jointpos joint="RFJ0" name="Sjp_RFJ0" />
    <jointpos joint="LFJ4" name="Sjp_LFJ4" />
    <jointpos joint="LFJ3" name="Sjp_LFJ3" />
    <jointpos joint="LFJ2" name="Sjp_LFJ2" />
    <jointpos joint="LFJ1" name="Sjp_LFJ1" />
    <jointpos joint="LFJ0" name="Sjp_LFJ0" />
    <jointpos joint="THJ4" name="Sjp_THJ4" />
    <jointpos joint="THJ3" name="Sjp_THJ3" />
    <jointpos joint="THJ2" name="Sjp_THJ2" />
    <jointpos joint="THJ1" name="Sjp_THJ1" />
    <jointpos joint="THJ0" name="Sjp_THJ0" />
  </sensor>
<equality /></mujoco>